Workbook

Sheet Plan
B2: THE PLAN · AT A GLANCE
B4: MISSION | C4: 330 → 280 lb by September, 275 meet class, JAN '27 meet.
B5: SPLIT | C5: Push / Pull / Legs, 3 days per week. Main lifts on percentage wave (see Training Log).
B6: CALORIES | C6: 2,225 to start. Intentionally low. As metabolism responds, we ramp food UP week over week.
B7: MACROS | C7: 225 g protein · 175 g carbs · 70 g fat
B8: CARDIO | C8: 30 min fasted walk, 4x per week. Before food, steady pace, daily if it feels good.
B9: CHECK-IN | C9: Every Saturday: weight + this spreadsheet to Chief. Tweaks for next 7 days come back Sunday.
B10: TRAINING MAX | C10: Training Max = 90% of true 1RM. You pick your starting numbers, we dial in from there.
B11: CYCLES | C11: 10 weeks per cycle (8 hard + deload + retest). 3 full cycles + peak block before meet.
B12: INCLINE | C12: Incline BB bench is primary press for the first blocks. Builds the shelf for flat bench later.
B13: SQUAT+DL | C13: Trying them same day first. If it's too much, we split them out. No ego, just adjust.
B14: MEALS | C14: Ask Chief anytime if you want meal ideas or a full meal plan to hit your macros. No charge.
B16: — PROGRAMMED BY JADEN / CHIEF · WE'VE GOT YOUR BACK · LET'S GO.

Sheet Dashboard
B3: BLAKE / THE 275 PROJECT
B4: MEET WINDOW · JAN '27 · 275 LB CLASS · COACHED BY JADEN / CHIEF
B6: STARTING | D6: CURRENT | F6: LOST SO FAR | H6: SEPT TARGET | J6: MEET WEIGHT
B7: 330 | D7: =IFERROR(LOOKUP(2,1/('Daily Log'!C3:C72<>""),'Daily Log'!C3:C72),330) | F7: =330-(IFERROR(LOOKUP(2,1/('Daily Log'!C3:C72<>""),'Daily Log'!C3:C72),330)) | H7: 280 | J7: 275
B9: DAILY FUEL TARGETS
B10: CALORIES | E10: PROTEIN | H10: CARBS | K10: FAT
B11: 2225 | E11: 225 g | H11: 175 g | K11: 70 g
B13: WEEKLY SUMMARY
B14: WEEK | C14: DATES | D14: AVG WT | E14: Δ VS START | F14: LIFT DAYS | G14: CARDIO | H14: AVG CAL | I14: AVG P | J14: AVG C | K14: AVG F | L14: NOTES
B15: 1 | C15: Apr 20 — Apr 26 | D15: =IFERROR(AVERAGEIF('Daily Log'!C3:C9,">0"),"—") | E15: =IFERROR(AVERAGEIF('Daily Log'!C3:C9,">0")-330,"—") | F15: =COUNTIF('Daily Log'!H3:H9,"Y") | G15: =COUNTIF('Daily Log'!J3:J9,">0") | H15: =IFERROR(AVERAGEIF('Daily Log'!K3:K9,">0"),"—") | I15: =IFERROR(AVERAGEIF('Daily Log'!L3:L9,">0"),"—") | J15: =IFERROR(AVERAGEIF('Daily Log'!M3:M9,">0"),"—") | K15: =IFERROR(AVERAGEIF('Daily Log'!N3:N9,">0"),"—")
B16: 2 | C16: Apr 27 — May 03 | D16: =IFERROR(AVERAGEIF('Daily Log'!C10:C16,">0"),"—") | E16: =IFERROR(AVERAGEIF('Daily Log'!C10:C16,">0")-330,"—") | F16: =COUNTIF('Daily Log'!H10:H16,"Y") | G16: =COUNTIF('Daily Log'!J10:J16,">0") | H16: =IFERROR(AVERAGEIF('Daily Log'!K10:K16,">0"),"—") | I16: =IFERROR(AVERAGEIF('Daily Log'!L10:L16,">0"),"—") | J16: =IFERROR(AVERAGEIF('Daily Log'!M10:M16,">0"),"—") | K16: =IFERROR(AVERAGEIF('Daily Log'!N10:N16,">0"),"—")
B17: 3 | C17: May 04 — May 10 | D17: =IFERROR(AVERAGEIF('Daily Log'!C17:C23,">0"),"—") | E17: =IFERROR(AVERAGEIF('Daily Log'!C17:C23,">0")-330,"—") | F17: =COUNTIF('Daily Log'!H17:H23,"Y") | G17: =COUNTIF('Daily Log'!J17:J23,">0") | H17: =IFERROR(AVERAGEIF('Daily Log'!K17:K23,">0"),"—") | I17: =IFERROR(AVERAGEIF('Daily Log'!L17:L23,">0"),"—") | J17: =IFERROR(AVERAGEIF('Daily Log'!M17:M23,">0"),"—") | K17: =IFERROR(AVERAGEIF('Daily Log'!N17:N23,">0"),"—")
B18: 4 | C18: May 11 — May 17 | D18: =IFERROR(AVERAGEIF('Daily Log'!C24:C30,">0"),"—") | E18: =IFERROR(AVERAGEIF('Daily Log'!C24:C30,">0")-330,"—") | F18: =COUNTIF('Daily Log'!H24:H30,"Y") | G18: =COUNTIF('Daily Log'!J24:J30,">0") | H18: =IFERROR(AVERAGEIF('Daily Log'!K24:K30,">0"),"—") | I18: =IFERROR(AVERAGEIF('Daily Log'!L24:L30,">0"),"—") | J18: =IFERROR(AVERAGEIF('Daily Log'!M24:M30,">0"),"—") | K18: =IFERROR(AVERAGEIF('Daily Log'!N24:N30,">0"),"—")
B19: 5 | C19: May 18 — May 24 | D19: =IFERROR(AVERAGEIF('Daily Log'!C31:C37,">0"),"—") | E19: =IFERROR(AVERAGEIF('Daily Log'!C31:C37,">0")-330,"—") | F19: =COUNTIF('Daily Log'!H31:H37,"Y") | G19: =COUNTIF('Daily Log'!J31:J37,">0") | H19: =IFERROR(AVERAGEIF('Daily Log'!K31:K37,">0"),"—") | I19: =IFERROR(AVERAGEIF('Daily Log'!L31:L37,">0"),"—") | J19: =IFERROR(AVERAGEIF('Daily Log'!M31:M37,">0"),"—") | K19: =IFERROR(AVERAGEIF('Daily Log'!N31:N37,">0"),"—")
B20: 6 | C20: May 25 — May 31 | D20: =IFERROR(AVERAGEIF('Daily Log'!C38:C44,">0"),"—") | E20: =IFERROR(AVERAGEIF('Daily Log'!C38:C44,">0")-330,"—") | F20: =COUNTIF('Daily Log'!H38:H44,"Y") | G20: =COUNTIF('Daily Log'!J38:J44,">0") | H20: =IFERROR(AVERAGEIF('Daily Log'!K38:K44,">0"),"—") | I20: =IFERROR(AVERAGEIF('Daily Log'!L38:L44,">0"),"—") | J20: =IFERROR(AVERAGEIF('Daily Log'!M38:M44,">0"),"—") | K20: =IFERROR(AVERAGEIF('Daily Log'!N38:N44,">0"),"—")
B21: 7 | C21: Jun 01 — Jun 07 | D21: =IFERROR(AVERAGEIF('Daily Log'!C45:C51,">0"),"—") | E21: =IFERROR(AVERAGEIF('Daily Log'!C45:C51,">0")-330,"—") | F21: =COUNTIF('Daily Log'!H45:H51,"Y") | G21: =COUNTIF('Daily Log'!J45:J51,">0") | H21: =IFERROR(AVERAGEIF('Daily Log'!K45:K51,">0"),"—") | I21: =IFERROR(AVERAGEIF('Daily Log'!L45:L51,">0"),"—") | J21: =IFERROR(AVERAGEIF('Daily Log'!M45:M51,">0"),"—") | K21: =IFERROR(AVERAGEIF('Daily Log'!N45:N51,">0"),"—")
B22: 8 | C22: Jun 08 — Jun 14 | D22: =IFERROR(AVERAGEIF('Daily Log'!C52:C58,">0"),"—") | E22: =IFERROR(AVERAGEIF('Daily Log'!C52:C58,">0")-330,"—") | F22: =COUNTIF('Daily Log'!H52:H58,"Y") | G22: =COUNTIF('Daily Log'!J52:J58,">0") | H22: =IFERROR(AVERAGEIF('Daily Log'!K52:K58,">0"),"—") | I22: =IFERROR(AVERAGEIF('Daily Log'!L52:L58,">0"),"—") | J22: =IFERROR(AVERAGEIF('Daily Log'!M52:M58,">0"),"—") | K22: =IFERROR(AVERAGEIF('Daily Log'!N52:N58,">0"),"—")
B23: 9 | C23: Jun 15 — Jun 21 | D23: =IFERROR(AVERAGEIF('Daily Log'!C59:C65,">0"),"—") | E23: =IFERROR(AVERAGEIF('Daily Log'!C59:C65,">0")-330,"—") | F23: =COUNTIF('Daily Log'!H59:H65,"Y") | G23: =COUNTIF('Daily Log'!J59:J65,">0") | H23: =IFERROR(AVERAGEIF('Daily Log'!K59:K65,">0"),"—") | I23: =IFERROR(AVERAGEIF('Daily Log'!L59:L65,">0"),"—") | J23: =IFERROR(AVERAGEIF('Daily Log'!M59:M65,">0"),"—") | K23: =IFERROR(AVERAGEIF('Daily Log'!N59:N65,">0"),"—")
B24: 10 | C24: Jun 22 — Jun 28 | D24: =IFERROR(AVERAGEIF('Daily Log'!C66:C72,">0"),"—") | E24: =IFERROR(AVERAGEIF('Daily Log'!C66:C72,">0")-330,"—") | F24: =COUNTIF('Daily Log'!H66:H72,"Y") | G24: =COUNTIF('Daily Log'!J66:J72,">0") | H24: =IFERROR(AVERAGEIF('Daily Log'!K66:K72,">0"),"—") | I24: =IFERROR(AVERAGEIF('Daily Log'!L66:L72,">0"),"—") | J24: =IFERROR(AVERAGEIF('Daily Log'!M66:M72,">0"),"—") | K24: =IFERROR(AVERAGEIF('Daily Log'!N66:N72,">0"),"—")
B27: PROGRAMMED BY JADEN / CHIEF · SEND EVERY SATURDAY · BCH FIT

Sheet Daily Log
A1: DAILY LOG · CYCLE 1 · APR 20 — JUN 28
A2: DATE | B2: DAY | C2: WEIGHT | D2: SLEEP | E2: CPAP | F2: ENERGY | G2: HUNGER | H2: TRAIN? | I2: SESSION | J2: CARDIO | K2: CAL | L2: PROTEIN | M2: CARBS | N2: FAT | O2: MACROS HIT | P2: NOTES
A3: 46132 | B3: 1 | H3: Y | I3: Push | O3: =IF(AND(K3>=2115,K3<=2335,L3>=215),"Y",IF(K3="","","N"))
A4: 46133 | B4: 2 | O4: =IF(AND(K4>=2115,K4<=2335,L4>=215),"Y",IF(K4="","","N"))
A5: 46134 | B5: 3 | H5: Y | I5: Pull | O5: =IF(AND(K5>=2115,K5<=2335,L5>=215),"Y",IF(K5="","","N"))
A6: 46135 | B6: 4 | O6: =IF(AND(K6>=2115,K6<=2335,L6>=215),"Y",IF(K6="","","N"))
A7: 46136 | B7: 5 | H7: Y | I7: Legs | O7: =IF(AND(K7>=2115,K7<=2335,L7>=215),"Y",IF(K7="","","N"))
A8: 46137 | B8: 6 | O8: =IF(AND(K8>=2115,K8<=2335,L8>=215),"Y",IF(K8="","","N"))
A9: 46138 | B9: 7 | O9: =IF(AND(K9>=2115,K9<=2335,L9>=215),"Y",IF(K9="","","N"))
A10: 46139 | B10: 8 | H10: Y | I10: Push | O10: =IF(AND(K10>=2115,K10<=2335,L10>=215),"Y",IF(K10="","","N"))
A11: 46140 | B11: 9 | O11: =IF(AND(K11>=2115,K11<=2335,L11>=215),"Y",IF(K11="","","N"))
A12: 46141 | B12: 10 | H12: Y | I12: Pull | O12: =IF(AND(K12>=2115,K12<=2335,L12>=215),"Y",IF(K12="","","N"))
A13: 46142 | B13: 11 | O13: =IF(AND(K13>=2115,K13<=2335,L13>=215),"Y",IF(K13="","","N"))
A14: 46143 | B14: 12 | H14: Y | I14: Legs | O14: =IF(AND(K14>=2115,K14<=2335,L14>=215),"Y",IF(K14="","","N"))
A15: 46144 | B15: 13 | O15: =IF(AND(K15>=2115,K15<=2335,L15>=215),"Y",IF(K15="","","N"))
A16: 46145 | B16: 14 | O16: =IF(AND(K16>=2115,K16<=2335,L16>=215),"Y",IF(K16="","","N"))
A17: 46146 | B17: 15 | H17: Y | I17: Push | O17: =IF(AND(K17>=2115,K17<=2335,L17>=215),"Y",IF(K17="","","N"))
A18: 46147 | B18: 16 | O18: =IF(AND(K18>=2115,K18<=2335,L18>=215),"Y",IF(K18="","","N"))
A19: 46148 | B19: 17 | H19: Y | I19: Pull | O19: =IF(AND(K19>=2115,K19<=2335,L19>=215),"Y",IF(K19="","","N"))
A20: 46149 | B20: 18 | O20: =IF(AND(K20>=2115,K20<=2335,L20>=215),"Y",IF(K20="","","N"))
A21: 46150 | B21: 19 | H21: Y | I21: Legs | O21: =IF(AND(K21>=2115,K21<=2335,L21>=215),"Y",IF(K21="","","N"))
A22: 46151 | B22: 20 | O22: =IF(AND(K22>=2115,K22<=2335,L22>=215),"Y",IF(K22="","","N"))
A23: 46152 | B23: 21 | O23: =IF(AND(K23>=2115,K23<=2335,L23>=215),"Y",IF(K23="","","N"))
A24: 46153 | B24: 22 | H24: Y | I24: Push | O24: =IF(AND(K24>=2115,K24<=2335,L24>=215),"Y",IF(K24="","","N"))
A25: 46154 | B25: 23 | O25: =IF(AND(K25>=2115,K25<=2335,L25>=215),"Y",IF(K25="","","N"))
A26: 46155 | B26: 24 | H26: Y | I26: Pull | O26: =IF(AND(K26>=2115,K26<=2335,L26>=215),"Y",IF(K26="","","N"))
A27: 46156 | B27: 25 | O27: =IF(AND(K27>=2115,K27<=2335,L27>=215),"Y",IF(K27="","","N"))
A28: 46157 | B28: 26 | H28: Y | I28: Legs | O28: =IF(AND(K28>=2115,K28<=2335,L28>=215),"Y",IF(K28="","","N"))
A29: 46158 | B29: 27 | O29: =IF(AND(K29>=2115,K29<=2335,L29>=215),"Y",IF(K29="","","N"))
A30: 46159 | B30: 28 | O30: =IF(AND(K30>=2115,K30<=2335,L30>=215),"Y",IF(K30="","","N"))
A31: 46160 | B31: 29 | H31: Y | I31: Push | O31: =IF(AND(K31>=2115,K31<=2335,L31>=215),"Y",IF(K31="","","N"))
A32: 46161 | B32: 30 | O32: =IF(AND(K32>=2115,K32<=2335,L32>=215),"Y",IF(K32="","","N"))
A33: 46162 | B33: 31 | H33: Y | I33: Pull | O33: =IF(AND(K33>=2115,K33<=2335,L33>=215),"Y",IF(K33="","","N"))
A34: 46163 | B34: 32 | O34: =IF(AND(K34>=2115,K34<=2335,L34>=215),"Y",IF(K34="","","N"))
A35: 46164 | B35: 33 | H35: Y | I35: Legs | O35: =IF(AND(K35>=2115,K35<=2335,L35>=215),"Y",IF(K35="","","N"))
A36: 46165 | B36: 34 | O36: =IF(AND(K36>=2115,K36<=2335,L36>=215),"Y",IF(K36="","","N"))
A37: 46166 | B37: 35 | O37: =IF(AND(K37>=2115,K37<=2335,L37>=215),"Y",IF(K37="","","N"))
A38: 46167 | B38: 36 | H38: Y | I38: Push | O38: =IF(AND(K38>=2115,K38<=2335,L38>=215),"Y",IF(K38="","","N"))
A39: 46168 | B39: 37 | O39: =IF(AND(K39>=2115,K39<=2335,L39>=215),"Y",IF(K39="","","N"))
A40: 46169 | B40: 38 | H40: Y | I40: Pull | O40: =IF(AND(K40>=2115,K40<=2335,L40>=215),"Y",IF(K40="","","N"))
...

Sheet Training Log
A1: TRAINING LOG · CYCLE 1 · MAIN LIFTS
A2: WK | B2: SESSION | C2: DATE | D2: LIFT | E2: SET 1 (wt × reps) | F2: SET 2 | G2: SET 3 | H2: AMRAP REPS | I2: NOTES
A3: WEEK 01 · 3×5, 1×5+ @ 65/70/75/75
A4: 1 | B4: Push | C4: 46132 | D4: Incline BB Bench
A5: 1 | B5: Push | C5: 46132 | D5: Military Press
A6: 1 | B6: Pull | C6: 46134 | D6: Barbell Rows
A7: 1 | B7: Pull | C7: 46134 | D7: Rack Pulls
A8: 1 | B8: Legs | C8: 46136 | D8: Back Squat
A9: 1 | B9: Legs | C9: 46136 | D9: Conv Deadlift
A11: WEEK 02 · 3×5, 1×5+ @ 67/72/77/77
A12: 2 | B12: Push | C12: 46139 | D12: Incline BB Bench
A13: 2 | B13: Push | C13: 46139 | D13: Military Press
A14: 2 | B14: Pull | C14: 46141 | D14: Barbell Rows
A15: 2 | B15: Pull | C15: 46141 | D15: Rack Pulls
A16: 2 | B16: Legs | C16: 46143 | D16: Back Squat
A17: 2 | B17: Legs | C17: 46143 | D17: Conv Deadlift
A19: WEEK 03 · 3×3, 1×3+ @ 70/75/80/80
A20: 3 | B20: Push | C20: 46146 | D20: Incline BB Bench
A21: 3 | B21: Push | C21: 46146 | D21: Military Press
A22: 3 | B22: Pull | C22: 46148 | D22: Barbell Rows
A23: 3 | B23: Pull | C23: 46148 | D23: Rack Pulls
A24: 3 | B24: Legs | C24: 46150 | D24: Back Squat
A25: 3 | B25: Legs | C25: 46150 | D25: Conv Deadlift
A27: WEEK 04 · 3×3, 1×3+ @ 72/77/82/82
A28: 4 | B28: Push | C28: 46153 | D28: Incline BB Bench
A29: 4 | B29: Push | C29: 46153 | D29: Military Press
A30: 4 | B30: Pull | C30: 46155 | D30: Barbell Rows
A31: 4 | B31: Pull | C31: 46155 | D31: Rack Pulls
A32: 4 | B32: Legs | C32: 46157 | D32: Back Squat
A33: 4 | B33: Legs | C33: 46157 | D33: Conv Deadlift
A35: WEEK 05 · DELOAD 3×5 @ 40/50/60
A36: 5 | B36: Push | C36: 46160 | D36: Incline BB Bench
A37: 5 | B37: Push | C37: 46160 | D37: Military Press
A38: 5 | B38: Pull | C38: 46162 | D38: Barbell Rows
A39: 5 | B39: Pull | C39: 46162 | D39: Rack Pulls
A40: 5 | B40: Legs | C40: 46164 | D40: Back Squat
A41: 5 | B41: Legs | C41: 46164 | D41: Conv Deadlift
A43: WEEK 06 · 3×3, 1×3 PAUSED @ 75/80/85/85
A44: 6 | B44: Push | C44: 46167 | D44: Incline BB Bench
A45: 6 | B45: Push | C45: 46167 | D45: Military Press
...
